Workbook
Name MATRICE: #REF!
Name MATRICE1: #REF!
Name MATRICE1: #REF!
Name MATRICEB: #REF!
Name MATRICEB: #REF!

Sheet ENTREE
A1: CODE | B1: Étiquettes de lignes | C1: quantite | D1: date entrée | E1: Vérif sage entrée | F1: vérif sage sortie
A2: FIXCARTEIMMARSAT | B2: CARTE IMMARSAT | C2: 5 | D2: 08/05/25 au 24/02/26 | E2: =VLOOKUP(A2,Tableau2[[Code Article]:[DATE INVENTAIRE]],11,FALSE) -> 46224
A3: TGSMCBL78F500ERK | B3: """ FEEDER CABLE 7/8"""" 500M (01 DRUM OF 500M) """ | C3: 393 | D3: 14/01/25 au 09/12/25 | E3: =VLOOKUP(A3,Tableau2[[Code Article]:[DATE INVENTAIRE]],11,FALSE) -> 46224
A4: TGSMPROUDUL20ERK | B4: "DUL 20 01, Digital Unit" | C4: 1 | D4: 45785 | E4: =VLOOKUP(A4,Tableau2[[Code Article]:[DATE INVENTAIRE]],11,FALSE) -> 46219 | F4: =VLOOKUP(A4,SORTIE!$A$2:$C$456,3,FALSE) -> #N/A
A5: TGSMPRUDUS411ERC | B5: "DUS 41 01,Digital unit" | C5: 2 | D5: 17/07/25 au 28/08/25 | E5: =VLOOKUP(A5,Tableau2[[Code Article]:[DATE INVENTAIRE]],11,FALSE) -> 46218
A6: TGSMPROUDUW31ERC | B6: "DUW, 31 01 Digital Unit" | C6: 31 | D6: 22/05/25 au 03/03/26 | E6: =VLOOKUP(A6,Tableau2[[Code Article]:[DATE INVENTAIRE]],11,FALSE) -> 46224
A7: TGSMTRCRUS1B3ERC | B7: "TRANSCEIVER/RRUS 01 B3,Radio | C7: 11 | D7: 20/03/25 au 05/03/26 | E7: =VLOOKUP(A7,Tableau2[[Code Article]:[DATE INVENTAIRE]],11,FALSE) -> 46216
A8: TGSMTRCRUS1B8ERC | B8: "TRANSCEIVER/RRUS 01B8,Radio U | C8: 95 | D8: 45776 | E8: =VLOOKUP(A8,Tableau2[[Code Article]:[DATE INVENTAIRE]],11,FALSE) -> 46224
A9: TGSMANTQB1L3HERC | B9: //QUAD BAND (1L+3H) | C9: 13 | D9: 45951 | E9: =VLOOKUP(A9,Tableau2[[Code Article]:[DATE INVENTAIRE]],11,FALSE) -> 46219 | F9: =VLOOKUP(A9,SORTIE!$A$2:$C$456,3,FALSE) -> 3
A10: TGSMANTTB1L2HERC | B10: //TRIBAND (1L+2H)_6880308NG | C10: 8 | D10: 45951 | E10: =VLOOKUP(A10,Tableau2[[Code Article]:[DATE INVENTAIRE]],11,FALSE) -> 46224
A11: TGSMANTM0678HERC | B11: 0.6 COMPACT ANTENNA 7/8 GHZ | C11: 224 | D11: 45988 | E11: =VLOOKUP(A11,Tableau2[[Code Article]:[DATE INVENTAIRE]],11,FALSE) -> 46224
A12: TGSMANT127G11ERC | B12: 1.2M DIA. PARABOLIC ANTENNA (V | C12: 66 | D12: 08/04/25 au 21/08/25 | E12: =VLOOKUP(A12,Tableau2[[Code Article]:[DATE INVENTAIRE]],11,FALSE) -> 46224
A13: TGSMANTM1278HERC | B13: 1.2M DIA. PARABOLIC ANTENNA 15GHZ | C13: 23 | D13: 13/05/25 au 06/11/25 | E13: =VLOOKUP(A13,Tableau2[[Code Article]:[DATE INVENTAIRE]],11,FALSE) -> 46224
A14: NMXTCBL16GN51XXX | B14: 16mm2, GNYE, (vert/jaune)5m, 1 lug with 2 M6 holes,_RPM1192062/5 | C14: 67 | D14: 45776 | E14: =VLOOKUP(A14,Tableau2[[Code Article]:[DATE INVENTAIRE]],11,FALSE) -> 46219 | F14: =VLOOKUP(A14,SORTIE!$A$2:$C$456,3,FALSE) -> #N/A
A15: NMXTCBL16GN31XXX | B15: 16mm2, GNYE, 3m_GROUNDING _RPM1192062/3 | C15: 39 | D15: 45951 | E15: =VLOOKUP(A15,Tableau2[[Code Article]:[DATE INVENTAIRE]],11,FALSE) -> 46219 | F15: =VLOOKUP(A15,SORTIE!$A$2:$C$456,3,FALSE) -> 39
A16: NMXTCDCAF363XXXX | B16: 1M DE CDC ACROFIL | C16: 1 | D16: 45951 | E16: =VLOOKUP(A16,Tableau2[[Code Article]:[DATE INVENTAIRE]],11,FALSE) -> 46219 | F16: =VLOOKUP(A16,SORTIE!$A$2:$C$456,3,FALSE) -> #N/A
A17: TGSMCRT1UDCDUERC | B17: 1U DCDU (Use SP-BMG 907 158/1 for spare_BMG907158/1 | C17: 1 | D17: 45785 | E17: =VLOOKUP(A17,Tableau2[[Code Article]:[DATE INVENTAIRE]],11,FALSE) -> 46224
A18: NMXTGLTPL2525XXX | B18: 2,5M DE GOULOTTE | C18: 7 | D18: 13/05/25 au 06/11/25 | E18: =VLOOKUP(A18,Tableau2[[Code Article]:[DATE INVENTAIRE]],11,FALSE) -> 46219 | F18: =VLOOKUP(A18,SORTIE!$A$2:$C$456,3,FALSE) -> 7
A19: TGSMTJARLL70UERC | B19: 2F LC-LC SM | C19: 405 | D19: 30/01/25 au 06/11/25 | E19: =VLOOKUP(A19,Tableau2[[Code Article]:[DATE INVENTAIRE]],11,FALSE) -> 46224
A20: TGSMCBL2FLL50ERC | B20: 2F LC(FullAXS)-LC SM 100M_RPM2531633/100M | C20: 878 | D20: 09/01/25 au 24/03/26 | E20: =VLOOKUP(A20,Tableau2[[Code Article]:[DATE INVENTAIRE]],11,FALSE) -> 46224
A21: NMXTCBLALC216XXX | B21: 2x16 mm2 UL LSOH Alu Cu screen TFL492326 500m | C21: 806 | D21: 45776 | E21: =VLOOKUP(A21,Tableau2[[Code Article]:[DATE INVENTAIRE]],11,FALSE) -> 46219 | F21: =VLOOKUP(A21,SORTIE!$A$2:$C$456,3,FALSE) -> 578
A22: NMXTCBLDC2X16XXX | B22: 2x16 sqmm_TFL492326/0 | C22: 39 | D22: 45951 | E22: =VLOOKUP(A22,Tableau2[[Code Article]:[DATE INVENTAIRE]],11,FALSE) -> 46219 | F22: =VLOOKUP(A22,SORTIE!$A$2:$C$456,3,FALSE) -> 36
A23: TGSMCBL2X6M5MERC | B23: 2x6mm2 (10AWG) 600V 90C UL 5m | C23: 2 | D23: 45951 | E23: =VLOOKUP(A23,Tableau2[[Code Article]:[DATE INVENTAIRE]],11,FALSE) -> 46224
A24: NMXTCBLDP2X6MERC | B24: 2x6mm2 DC Power Cable No CPR No UL | C24: 8540 | D24: 45988 | E24: =VLOOKUP(A24,Tableau2[[Code Article]:[DATE INVENTAIRE]],11,FALSE) -> 46224
A25: TMXTREBD3EGENXXX | B25: 36110 MAINSTREET | C25: 1 | D25: 08/04/25 au 21/08/25 | E25: =VLOOKUP(A25,Tableau2[[Code Article]:[DATE INVENTAIRE]],11,FALSE) -> 46216
A26: NANOSIMS | B26: 4FF NANO JAVA SAT SIM CARO | C26: 88 | D26: 13/05/25 au 06/11/25 | E26: =VLOOKUP(A26,Tableau2[[Code Article]:[DATE INVENTAIRE]],11,FALSE) -> 46219 | F26: =VLOOKUP(A26,SORTIE!$A$2:$C$456,3,FALSE) -> 88
A27: NMXTTUBSUPBALXXX | B27: TUBES SUPPORT | C27: 4 | D27: 45776 | E27: =VLOOKUP(A27,Tableau2[[Code Article]:[DATE INVENTAIRE]],11,FALSE) -> 46219 | F27: =VLOOKUP(A27,SORTIE!$A$2:$C$456,3,FALSE) -> #N/A
A28: TGSMANT06PPB2XXX | B28: 6-Port Antenna LB/2HB 2.7m_84510866 | C28: 99 | D28: 45951 | E28: =VLOOKUP(A28,Tableau2[[Code Article]:[DATE INVENTAIRE]],11,FALSE) -> 46224
A29: FIXTCUIPOTBOIS9MXXX | B29: 9M 140/160MM WOODEN POLES | C29: 14 | D29: 45951 | E29: =VLOOKUP(A29,Tableau2[[Code Article]:[DATE INVENTAIRE]],11,FALSE) -> 46219 | F29: =VLOOKUP(A29,SORTIE!$A$2:$C$456,3,FALSE) -> #N/A
A30: SIM DROP ABONNE | B30: ABONNE DROP 128K JAVA | C30: 1 | D30: 45785 | E30: =VLOOKUP(A30,Tableau2[[Code Article]:[DATE INVENTAIRE]],11,FALSE) -> 46219 | F30: =VLOOKUP(A30,SORTIE!$A$2:$C$456,3,FALSE) -> 1
A31: ISHLACCLAMTUBERC | B31: ACCESSOIRE LAMPE | C31: 1 | D31: 17/07/25 au 28/08/25 | E31: =VLOOKUP(A31,Tableau2[[Code Article]:[DATE INVENTAIRE]],11,FALSE) -> 46219 | F31: =VLOOKUP(A31,SORTIE!$A$2:$C$456,3,FALSE) -> 1
A32: TMXTACCRCK42UXXX | B32: ACCESSOIRE RACK | C32: 14 | D32: 22/05/25 au 03/03/26 | E32: =VLOOKUP(A32,Tableau2[[Code Article]:[DATE INVENTAIRE]],11,FALSE) -> 46219 | F32: =VLOOKUP(A32,SORTIE!$A$2:$C$456,3,FALSE) -> #N/A
A33: TGSMACU01XXXXERK | B33: ACCU 01 | C33: 1 | D33: 45776 | E33: =VLOOKUP(A33,Tableau2[[Code Article]:[DATE INVENTAIRE]],11,FALSE) -> 46219 | F33: =VLOOKUP(A33,SORTIE!$A$2:$C$456,3,FALSE) -> #N/A
A34: NMXTBAT12V210NSB | B34: ACCUMULATOR/NSB RED 210 (4x12V) 210Ah BKC90106/155 | C34: 16 | D34: 45951 | E34: =VLOOKUP(A34,Tableau2[[Code Article]:[DATE INVENTAIRE]],11,FALSE) -> 46224
A35: TMXTREBD3EGENXXX | B35: ADAPTEUR | C35: 262 | D35: 45951 | E35: =VLOOKUP(A35,Tableau2[[Code Article]:[DATE INVENTAIRE]],11,FALSE) -> 46216
A36: TFHXCHSADR25ESGM | B36: ADR 2500 EXTRA | C36: 11 | D36: 45988 | E36: =VLOOKUP(A36,Tableau2[[Code Article]:[DATE INVENTAIRE]],11,FALSE) -> 46219 | F36: =VLOOKUP(A36,SORTIE!$A$2:$C$456,3,FALSE) -> #N/A
A37: TMXTFANADR155SGM | B37: ADR-SAGEM 155C | C37: 15 | D37: 08/04/25 au 21/08/25 | E37: =VLOOKUP(A37,Tableau2[[Code Article]:[DATE INVENTAIRE]],11,FALSE) -> 46218
A38: MPRT0000042620XXX | B38: AFFICHE 40X60CM | C38: 2084 | D38: 13/05/25 au 06/11/25 | E38: =VLOOKUP(A38,Tableau2[[Code Article]:[DATE INVENTAIRE]],11,FALSE) -> 46224
A39: MPRT000004123XXX | B39: AFFICHE 90X40CM | C39: 101 | D39: 45776 | E39: =VLOOKUP(A39,Tableau2[[Code Article]:[DATE INVENTAIRE]],11,FALSE) -> 46224
A40: MGDIAGRAPH001XXX | B40: AGRAPHEUSE | C40: 2 | D40: 45951 | E40: =VLOOKUP(A40,Tableau2[[Code Article]:[DATE INVENTAIRE]],11,FALSE) -> 46216
...

Sheet ARTICLES SAGE
A1: Code Article | B1: descriptions | C1: STOCK FIN DECEMBRE 2024 SAGE | D1: SKU | E1: Entrée 01 Janv 2025 au 10 juillet 2026 | F1: sortie 01 Janv 2025 au 10 juillet 2026 | G1: stock final au 10 juillet 2026 | H1: inventaire juillet 2026 | I1: écart (I-J) | J1: Explications des Ecarts | K1: DATE INVENTAIRE | L1: ENTREE LE 23/07/26 AU 14/07/26 | M1: SORTIE 23/07/26 AU 14/10/26
A2: TGSMANTX3B806XXX | B2: Antenna triple band Antenna XX | C2: 3 | D2: PIE | E2: 0 | F2: 0 | G2: =Tableau2[[#This Row],[STOCK FIN DECEMBRE 2024 SAGE]]+Tableau2[[#This Row],[Entrée 01 Janv 2025 au 10 juillet 2026]]-Tableau2[[#This Row],[sortie 01 Janv 2025 au 10 juillet 2026]] -> 3 | I2: =Tableau2[[#This Row],[inventaire juillet 2026 ]]-Tableau2[[#This Row],[stock final au 10 juillet 2026]] -> -3 | K2: 46224 | L2: =VLOOKUP(Tableau2[[#This Row],[Code Article]],'ENTREE APRES INV'!A1:F1010,6,0) -> #N/A | M2: =VLOOKUP(Tableau2[[#This Row],[Code Article]],'SORTIE APRES INV'!A1:D411,4,0) -> #N/A
A3: TCDMCBLPDRW14XXX | B3: Power Distribution Rack,W14A3Z | C3: 3 | D3: PIE | E3: 0 | F3: 0 | G3: =Tableau2[[#This Row],[STOCK FIN DECEMBRE 2024 SAGE]]+Tableau2[[#This Row],[Entrée 01 Janv 2025 au 10 juillet 2026]]-Tableau2[[#This Row],[sortie 01 Janv 2025 au 10 juillet 2026]] -> 3 | H3: 3 | I3: =Tableau2[[#This Row],[inventaire juillet 2026 ]]-Tableau2[[#This Row],[stock final au 10 juillet 2026]] -> 0 | K3: 46224 | L3: =VLOOKUP(Tableau2[[#This Row],[Code Article]],'ENTREE APRES INV'!A2:F1011,6,0) -> #N/A | M3: =VLOOKUP(Tableau2[[#This Row],[Code Article]],'SORTIE APRES INV'!A2:D412,4,0) -> #N/A
A4: TCUIBMX56PVIDGEK | B4: Bmx 56 paires (vide) | C4: 2 | D4: PIE | E4: =VLOOKUP(Tableau2[[#This Row],[Code Article]],ENTREE!A59:C755,3,FALSE) -> 9 | F4: 0 | G4: =Tableau2[[#This Row],[STOCK FIN DECEMBRE 2024 SAGE]]+Tableau2[[#This Row],[Entrée 01 Janv 2025 au 10 juillet 2026]]-Tableau2[[#This Row],[sortie 01 Janv 2025 au 10 juillet 2026]] -> 11 | H4: 11 | I4: =Tableau2[[#This Row],[inventaire juillet 2026 ]]-Tableau2[[#This Row],[stock final au 10 juillet 2026]] -> 0 | K4: 46216 | L4: =VLOOKUP(Tableau2[[#This Row],[Code Article]],'ENTREE APRES INV'!A3:F1012,6,0) -> #N/A | M4: =VLOOKUP(Tableau2[[#This Row],[Code Article]],'SORTIE APRES INV'!A3:D413,4,0) -> #N/A
A5: TGSMANTXPL84XERK | B5: ANTENNA XPOL C-PANEL 806-960/8 | C5: 2 | D5: PIE | E5: 0 | F5: =+SORTIE!C47 -> 2 | G5: =Tableau2[[#This Row],[STOCK FIN DECEMBRE 2024 SAGE]]+Tableau2[[#This Row],[Entrée 01 Janv 2025 au 10 juillet 2026]]-Tableau2[[#This Row],[sortie 01 Janv 2025 au 10 juillet 2026]] -> 0 | I5: =Tableau2[[#This Row],[inventaire juillet 2026 ]]-Tableau2[[#This Row],[stock final au 10 juillet 2026]] -> 0 | K5: 46224 | L5: =VLOOKUP(Tableau2[[#This Row],[Code Article]],'ENTREE APRES INV'!A4:F1013,6,0) -> #N/A | M5: =VLOOKUP(Tableau2[[#This Row],[Code Article]],'SORTIE APRES INV'!A4:D414,4,0) -> #N/A
A6: TGSMANTDBC2HXERC | B6: ANTENNA DUAL COLUMN BAND 2H_61 | C6: 9 | D6: PIE | E6: =+ENTREE!C55 -> 58 | F6: =+SORTIE!C46 -> 58 | G6: =Tableau2[[#This Row],[STOCK FIN DECEMBRE 2024 SAGE]]+Tableau2[[#This Row],[Entrée 01 Janv 2025 au 10 juillet 2026]]-Tableau2[[#This Row],[sortie 01 Janv 2025 au 10 juillet 2026]] -> 9 | H6: 9 | I6: =Tableau2[[#This Row],[inventaire juillet 2026 ]]-Tableau2[[#This Row],[stock final au 10 juillet 2026]] -> 0 | K6: 46224 | L6: =VLOOKUP(Tableau2[[#This Row],[Code Article]],'ENTREE APRES INV'!A5:F1014,6,0) -> #N/A | M6: =VLOOKUP(Tableau2[[#This Row],[Code Article]],'SORTIE APRES INV'!A5:D415,4,0) -> #N/A
A7: TCUIPEKR5XXXXGEK | B7: Peca R5 | C7: 1 | D7: PIE | E7: =+ENTREE!C683 -> 34 | F7: 0 | G7: =Tableau2[[#This Row],[STOCK FIN DECEMBRE 2024 SAGE]]+Tableau2[[#This Row],[Entrée 01 Janv 2025 au 10 juillet 2026]]-Tableau2[[#This Row],[sortie 01 Janv 2025 au 10 juillet 2026]] -> 35 | H7: 35 | I7: =Tableau2[[#This Row],[inventaire juillet 2026 ]]-Tableau2[[#This Row],[stock final au 10 juillet 2026]] -> 0 | K7: 46224 | L7: =VLOOKUP(Tableau2[[#This Row],[Code Article]],'ENTREE APRES INV'!A6:F1015,6,0) -> #N/A | M7: =VLOOKUP(Tableau2[[#This Row],[Code Article]],'SORTIE APRES INV'!A6:D416,4,0) -> #N/A
A8: TFOXCBLS2FMUAPHO | B8: CABLE 2FO SM MULTI-USAGE G657 | C8: 258 | D8: PIE | E8: =VLOOKUP(Tableau2[[#This Row],[Code Article]],ENTREE!A68:C780,3,FALSE) -> 837 | F8: =VLOOKUP(Tableau2[[#This Row],[Code Article]],SORTIE!A75:C580,3,FALSE) -> 1095 | G8: =Tableau2[[#This Row],[STOCK FIN DECEMBRE 2024 SAGE]]+Tableau2[[#This Row],[Entrée 01 Janv 2025 au 10 juillet 2026]]-Tableau2[[#This Row],[sortie 01 Janv 2025 au 10 juillet 2026]] -> 0 | I8: =Tableau2[[#This Row],[inventaire juillet 2026 ]]-Tableau2[[#This Row],[stock final au 10 juillet 2026]] -> 0 | K8: 46224 | L8: =VLOOKUP(Tableau2[[#This Row],[Code Article]],'ENTREE APRES INV'!A7:F1016,6,0) -> #N/A | M8: =VLOOKUP(Tableau2[[#This Row],[Code Article]],'SORTIE APRES INV'!A7:D417,4,0) -> #N/A
A9: TGSMANT06PPB2XXX | B9: 6-Port Antenna LB/2HB 2,7m 845 | C9: 47 | D9: PIE | E9: 86 | F9: 133 | G9: =Tableau2[[#This Row],[STOCK FIN DECEMBRE 2024 SAGE]]+Tableau2[[#This Row],[Entrée 01 Janv 2025 au 10 juillet 2026]]-Tableau2[[#This Row],[sortie 01 Janv 2025 au 10 juillet 2026]] -> 0 | I9: =Tableau2[[#This Row],[inventaire juillet 2026 ]]-Tableau2[[#This Row],[stock final au 10 juillet 2026]] -> 0 | K9: 46224 | L9: =VLOOKUP(Tableau2[[#This Row],[Code Article]],'ENTREE APRES INV'!A8:F1017,6,0) -> #N/A | M9: =VLOOKUP(Tableau2[[#This Row],[Code Article]],'SORTIE APRES INV'!A8:D418,4,0) -> #N/A
A10: TCS3RCKOSS2XXXXX | B10: Rack OSS2 | C10: 1 | D10: PIE | E10: 0 | F10: 0 | G10: =Tableau2[[#This Row],[STOCK FIN DECEMBRE 2024 SAGE]]+Tableau2[[#This Row],[Entrée 01 Janv 2025 au 10 juillet 2026]]-Tableau2[[#This Row],[sortie 01 Janv 2025 au 10 juillet 2026]] -> 1 | H10: 1 | I10: =Tableau2[[#This Row],[inventaire juillet 2026 ]]-Tableau2[[#This Row],[stock final au 10 juillet 2026]] -> 0 | K10: 46224 | L10: =VLOOKUP(Tableau2[[#This Row],[Code Article]],'ENTREE APRES INV'!A9:F1018,6,0) -> #N/A | M10: =VLOOKUP(Tableau2[[#This Row],[Code Article]],'SORTIE APRES INV'!A9:D419,4,0) -> #N/A
A11: TCUICBL98X056GEK | B11: Câble 98-056-6 | C11: 254 | D11: PIE | E11: 158 | F11: 0 | G11: =Tableau2[[#This Row],[STOCK FIN DECEMBRE 2024 SAGE]]+Tableau2[[#This Row],[Entrée 01 Janv 2025 au 10 juillet 2026]]-Tableau2[[#This Row],[sortie 01 Janv 2025 au 10 juillet 2026]] -> 412 | H11: 412 | I11: =Tableau2[[#This Row],[inventaire juillet 2026 ]]-Tableau2[[#This Row],[stock final au 10 juillet 2026]] -> 0 | K11: 46216 | L11: =VLOOKUP(Tableau2[[#This Row],[Code Article]],'ENTREE APRES INV'!A10:F1019,6,0) -> #N/A | M11: =VLOOKUP(Tableau2[[#This Row],[Code Article]],'SORTIE APRES INV'!A10:D420,4,0) -> #N/A
A12: TCUICBLNEO599GEK | B12: Câble néoprène 5/99 | C12: 7657 | D12: PIE | E12: =VLOOKUP(Tableau2[[#This Row],[Code Article]],ENTREE!A2:C588,3,FALSE) -> 14650 | F12: =VLOOKUP(Tableau2[[#This Row],[Code Article]],SORTIE!A3:C386,3,FALSE) -> 22307 | G12: =Tableau2[[#This Row],[STOCK FIN DECEMBRE 2024 SAGE]]+Tableau2[[#This Row],[Entrée 01 Janv 2025 au 10 juillet 2026]]-Tableau2[[#This Row],[sortie 01 Janv 2025 au 10 juillet 2026]] -> 0 | H12: 0 | I12: =Tableau2[[#This Row],[inventaire juillet 2026 ]]-Tableau2[[#This Row],[stock final au 10 juillet 2026]] -> 0 | K12: 46224 | L12: =VLOOKUP(Tableau2[[#This Row],[Code Article]],'ENTREE APRES INV'!A11:F1020,6,0) -> 50 | M12: =VLOOKUP(Tableau2[[#This Row],[Code Article]],'SORTIE APRES INV'!A11:D421,4,0) -> #N/A
A13: TFHXCBLCONTNCNEK | B13: CONNECTEUR | C13: 8 | D13: PIE | E13: 1074 | F13: =VLOOKUP(Tableau2[[#This Row],[Code Article]],SORTIE!A4:C387,3,FALSE) -> 1532 | G13: =Tableau2[[#This Row],[STOCK FIN DECEMBRE 2024 SAGE]]+Tableau2[[#This Row],[Entrée 01 Janv 2025 au 10 juillet 2026]]-Tableau2[[#This Row],[sortie 01 Janv 2025 au 10 juillet 2026]] -> -450 | H13: 62 | I13: =Tableau2[[#This Row],[inventaire juillet 2026 ]]-Tableau2[[#This Row],[stock final au 10 juillet 2026]] -> 512 | K13: 46216 | L13: =VLOOKUP(Tableau2[[#This Row],[Code Article]],'ENTREE APRES INV'!A12:F1021,6,0) -> #N/A | M13: =VLOOKUP(Tableau2[[#This Row],[Code Article]],'SORTIE APRES INV'!A12:D422,4,0) -> #N/A
A14: TFOXCBLOP12STXXX | B14: CABLE OPTIQUE 12FO SOUS TERRAI | C14: 91 | D14: PIE | E14: =VLOOKUP(Tableau2[[#This Row],[Code Article]],ENTREE!A3:C590,3,FALSE) -> 2497 | F14: =VLOOKUP(Tableau2[[#This Row],[Code Article]],SORTIE!A5:C388,3,FALSE) -> 2588 | G14: =Tableau2[[#This Row],[STOCK FIN DECEMBRE 2024 SAGE]]+Tableau2[[#This Row],[Entrée 01 Janv 2025 au 10 juillet 2026]]-Tableau2[[#This Row],[sortie 01 Janv 2025 au 10 juillet 2026]] -> 0 | I14: =Tableau2[[#This Row],[inventaire juillet 2026 ]]-Tableau2[[#This Row],[stock final au 10 juillet 2026]] -> 0 | K14: 46224 | L14: =VLOOKUP(Tableau2[[#This Row],[Code Article]],'ENTREE APRES INV'!A13:F1022,6,0) -> #N/A | M14: =VLOOKUP(Tableau2[[#This Row],[Code Article]],'SORTIE APRES INV'!A13:D423,4,0) -> #N/A
A15: TFOXCBLR2FOXXNEX | B15: SP1799 - CABLE DE RACCORDEMENT | C15: 241 | D15: PIE | E15: 0 | F15: 0 | G15: =Tableau2[[#This Row],[STOCK FIN DECEMBRE 2024 SAGE]]+Tableau2[[#This Row],[Entrée 01 Janv 2025 au 10 juillet 2026]]-Tableau2[[#This Row],[sortie 01 Janv 2025 au 10 juillet 2026]] -> 241 | H15: 241 | I15: =Tableau2[[#This Row],[inventaire juillet 2026 ]]-Tableau2[[#This Row],[stock final au 10 juillet 2026]] -> 0 | K15: 46224 | L15: =VLOOKUP(Tableau2[[#This Row],[Code Article]],'ENTREE APRES INV'!A14:F1023,6,0) -> #N/A | M15: =VLOOKUP(Tableau2[[#This Row],[Code Article]],'SORTIE APRES INV'!A14:D424,4,0) -> #N/A
A16: TFOXOUTPM3921XXX | B16: Pince à dénuder la gaine et la | C16: 14 | D16: PIE | E16: 0 | F16: 0 | G16: =Tableau2[[#This Row],[STOCK FIN DECEMBRE 2024 SAGE]]+Tableau2[[#This Row],[Entrée 01 Janv 2025 au 10 juillet 2026]]-Tableau2[[#This Row],[sortie 01 Janv 2025 au 10 juillet 2026]] -> 14 | H16: 14 | I16: =Tableau2[[#This Row],[inventaire juillet 2026 ]]-Tableau2[[#This Row],[stock final au 10 juillet 2026]] -> 0 | K16: 46224 | L16: =VLOOKUP(Tableau2[[#This Row],[Code Article]],'ENTREE APRES INV'!A15:F1024,6,0) -> #N/A | M16: =VLOOKUP(Tableau2[[#This Row],[Code Article]],'SORTIE APRES INV'!A15:D425,4,0) -> #N/A
A17: TFOXSUPPLSPT1XXX | B17: Support plastique special pote | C17: 1 | D17: PIE | E17: 0 | F17: 0 | G17: =Tableau2[[#This Row],[STOCK FIN DECEMBRE 2024 SAGE]]+Tableau2[[#This Row],[Entrée 01 Janv 2025 au 10 juillet 2026]]-Tableau2[[#This Row],[sortie 01 Janv 2025 au 10 juillet 2026]] -> 1 | H17: 1 | I17: =Tableau2[[#This Row],[inventaire juillet 2026 ]]-Tableau2[[#This Row],[stock final au 10 juillet 2026]] -> 0 | K17: 46225 | L17: =VLOOKUP(Tableau2[[#This Row],[Code Article]],'ENTREE APRES INV'!A16:F1025,6,0) -> #N/A | M17: =VLOOKUP(Tableau2[[#This Row],[Code Article]],'SORTIE APRES INV'!A16:D426,4,0) -> #N/A
A18: TGSMACCRETU3GERC | B18: RETU for Kathrein antennas, 3GPP | C18: 9 | D18: PIE | E18: =VLOOKUP(Tableau2[[#This Row],[Code Article]],ENTREE!A5:C594,3,FALSE) -> 93 | F18: =VLOOKUP(Tableau2[[#This Row],[Code Article]],SORTIE!A8:C392,3,FALSE) -> 87 | G18: =Tableau2[[#This Row],[STOCK FIN DECEMBRE 2024 SAGE]]+Tableau2[[#This Row],[Entrée 01 Janv 2025 au 10 juillet 2026]]-Tableau2[[#This Row],[sortie 01 Janv 2025 au 10 juillet 2026]] -> 15 | H18: 15 | I18: =Tableau2[[#This Row],[inventaire juillet 2026 ]]-Tableau2[[#This Row],[stock final au 10 juillet 2026]] -> 0 | K18: 46224 | L18: =VLOOKUP(Tableau2[[#This Row],[Code Article]],'ENTREE APRES INV'!A17:F1026,6,0) -> #N/A | M18: =VLOOKUP(Tableau2[[#This Row],[Code Article]],'SORTIE APRES INV'!A17:D427,4,0) -> #N/A
A19: INFODISQUEDURXXX | B19: DISQUE DUR | C19: 19 | D19: PIE | E19: 17 | F19: =VLOOKUP(Tableau2[[#This Row],[Code Article]],SORTIE!A9:C393,3,FALSE) -> 19 | G19: =Tableau2[[#This Row],[STOCK FIN DECEMBRE 2024 SAGE]]+Tableau2[[#This Row],[Entrée 01 Janv 2025 au 10 juillet 2026]]-Tableau2[[#This Row],[sortie 01 Janv 2025 au 10 juillet 2026]] -> 17 | H19: 17 | I19: =Tableau2[[#This Row],[inventaire juillet 2026 ]]-Tableau2[[#This Row],[stock final au 10 juillet 2026]] -> 0 | K19: 46216 | L19: =VLOOKUP(Tableau2[[#This Row],[Code Article]],'ENTREE APRES INV'!A18:F1027,6,0) -> #N/A | M19: =VLOOKUP(Tableau2[[#This Row],[Code Article]],'SORTIE APRES INV'!A18:D428,4,0) -> #N/A
A20: NMXTCBLFLX022XXX | B20: Cable filotex SMBL 19x0,22 ave | C20: 12 | D20: PIE | E20: 0 | F20: 0 | G20: =Tableau2[[#This Row],[STOCK FIN DECEMBRE 2024 SAGE]]+Tableau2[[#This Row],[Entrée 01 Janv 2025 au 10 juillet 2026]]-Tableau2[[#This Row],[sortie 01 Janv 2025 au 10 juillet 2026]] -> 12 | H20: 12 | I20: =Tableau2[[#This Row],[inventaire juillet 2026 ]]-Tableau2[[#This Row],[stock final au 10 juillet 2026]] -> 0 | K20: 46216 | L20: =VLOOKUP(Tableau2[[#This Row],[Code Article]],'ENTREE APRES INV'!A19:F1028,6,0) -> #N/A | M20: =VLOOKUP(Tableau2[[#This Row],[Code Article]],'SORTIE APRES INV'!A19:D429,4,0) -> #N/A
A21: NMXTFLTAIRXXXXXX | B21: FILTRE A AIR | C21: 14 | D21: PIE | E21: 3 | F21: =VLOOKUP(Tableau2[[#This Row],[Code Article]],SORTIE!A12:C396,3,FALSE) -> 3 | G21: =Tableau2[[#This Row],[STOCK FIN DECEMBRE 2024 SAGE]]+Tableau2[[#This Row],[Entrée 01 Janv 2025 au 10 juillet 2026]]-Tableau2[[#This Row],[sortie 01 Janv 2025 au 10 juillet 2026]] -> 14 | H21: 14 | I21: =Tableau2[[#This Row],[inventaire juillet 2026 ]]-Tableau2[[#This Row],[stock final au 10 juillet 2026]] -> 0 | K21: 46217 | L21: =VLOOKUP(Tableau2[[#This Row],[Code Article]],'ENTREE APRES INV'!A20:F1029,6,0) -> #N/A | M21: =VLOOKUP(Tableau2[[#This Row],[Code Article]],'SORTIE APRES INV'!A20:D430,4,0) -> #N/A
A22: QLCEPNEUPNEUXXXX | B22: PNEU | C22: 5 | D22: PIE | E22: =VLOOKUP(Tableau2[[#This Row],[Code Article]],ENTREE!A7:C599,3,FALSE) -> 21 | F22: 0 | G22: =Tableau2[[#This Row],[STOCK FIN DECEMBRE 2024 SAGE]]+Tableau2[[#This Row],[Entrée 01 Janv 2025 au 10 juillet 2026]]-Tableau2[[#This Row],[sortie 01 Janv 2025 au 10 juillet 2026]] -> 26 | H22: 26 | I22: =Tableau2[[#This Row],[inventaire juillet 2026 ]]-Tableau2[[#This Row],[stock final au 10 juillet 2026]] -> 0 | K22: 46216 | L22: =VLOOKUP(Tableau2[[#This Row],[Code Article]],'ENTREE APRES INV'!A21:F1030,6,0) -> 1 | M22: =VLOOKUP(Tableau2[[#This Row],[Code Article]],'SORTIE APRES INV'!A21:D431,4,0) -> #N/A
A23: TFOXCBLOSSA12HAW | B23: Optical Fiber Cable,Outdoor se | C23: 2957 | D23: PIE | E23: 0 | F23: 0 | G23: =Tableau2[[#This Row],[STOCK FIN DECEMBRE 2024 SAGE]]+Tableau2[[#This Row],[Entrée 01 Janv 2025 au 10 juillet 2026]]-Tableau2[[#This Row],[sortie 01 Janv 2025 au 10 juillet 2026]] -> 2957 | H23: 2957 | I23: =Tableau2[[#This Row],[inventaire juillet 2026 ]]-Tableau2[[#This Row],[stock final au 10 juillet 2026]] -> 0 | K23: 46224 | L23: =VLOOKUP(Tableau2[[#This Row],[Code Article]],'ENTREE APRES INV'!A22:F1031,6,0) -> #N/A | M23: =VLOOKUP(Tableau2[[#This Row],[Code Article]],'SORTIE APRES INV'!A22:D432,4,0) -> #N/A
A24: TGSMACCADKWLCXXX | B24: Standard Downtilt kit (Wind lo | C24: 28 | D24: PIE | E24: =VLOOKUP(Tableau2[[#This Row],[Code Article]],ENTREE!A9:C602,3,FALSE) -> 278 | F24: 0 | G24: =Tableau2[[#This Row],[STOCK FIN DECEMBRE 2024 SAGE]]+Tableau2[[#This Row],[Entrée 01 Janv 2025 au 10 juillet 2026]]-Tableau2[[#This Row],[sortie 01 Janv 2025 au 10 juillet 2026]] -> 306 | H24: 306 | I24: =Tableau2[[#This Row],[inventaire juillet 2026 ]]-Tableau2[[#This Row],[stock final au 10 juillet 2026]] -> 0 | K24: 46225 | L24: =VLOOKUP(Tableau2[[#This Row],[Code Article]],'ENTREE APRES INV'!A23:F1032,6,0) -> #N/A | M24: =VLOOKUP(Tableau2[[#This Row],[Code Article]],'SORTIE APRES INV'!A23:D433,4,0) -> #N/A
A25: AMOIFAICHAXXXXXX | B25: CHAISE | C25: 39 | D25: PIE | E25: =VLOOKUP(Tableau2[[#This Row],[Code Article]],ENTREE!A10:C604,3,FALSE) -> 109 | F25: =VLOOKUP(Tableau2[[#This Row],[Code Article]],SORTIE!A17:C402,3,FALSE) -> 148 | G25: =Tableau2[[#This Row],[STOCK FIN DECEMBRE 2024 SAGE]]+Tableau2[[#This Row],[Entrée 01 Janv 2025 au 10 juillet 2026]]-Tableau2[[#This Row],[sortie 01 Janv 2025 au 10 juillet 2026]] -> 0 | H25: 0 | I25: =Tableau2[[#This Row],[inventaire juillet 2026 ]]-Tableau2[[#This Row],[stock final au 10 juillet 2026]] -> 0 | K25: 46224 | L25: =VLOOKUP(Tableau2[[#This Row],[Code Article]],'ENTREE APRES INV'!A24:F1033,6,0) -> #N/A | M25: =VLOOKUP(Tableau2[[#This Row],[Code Article]],'SORTIE APRES INV'!A24:D434,4,0) -> #N/A
A26: CINFRUBFAT124XXX | B26: RUBAN POUR FAX T102/104 PC 74 | C26: 2 | D26: PIE | E26: 0 | F26: 0 | G26: =Tableau2[[#This Row],[STOCK FIN DECEMBRE 2024 SAGE]]+Tableau2[[#This Row],[Entrée 01 Janv 2025 au 10 juillet 2026]]-Tableau2[[#This Row],[sortie 01 Janv 2025 au 10 juillet 2026]] -> 2 | H26: 2 | I26: =Tableau2[[#This Row],[inventaire juillet 2026 ]]-Tableau2[[#This Row],[stock final au 10 juillet 2026]] -> 0 | K26: 46224 | L26: =VLOOKUP(Tableau2[[#This Row],[Code Article]],'ENTREE APRES INV'!A25:F1034,6,0) -> #N/A | M26: =VLOOKUP(Tableau2[[#This Row],[Code Article]],'SORTIE APRES INV'!A25:D435,4,0) -> #N/A
A27: CINFSOUSSF126DEL | B27: Souris sans fil Dell WM126 | C27: 2 | D27: PIE | E27: 24 | F27: =VLOOKUP(Tableau2[[#This Row],[Code Article]],SORTIE!A18:C404,3,FALSE) -> 26 | G27: =Tableau2[[#This Row],[STOCK FIN DECEMBRE 2024 SAGE]]+Tableau2[[#This Row],[Entrée 01 Janv 2025 au 10 juillet 2026]]-Tableau2[[#This Row],[sortie 01 Janv 2025 au 10 juillet 2026]] -> 0 | H27: 0 | I27: =Tableau2[[#This Row],[inventaire juillet 2026 ]]-Tableau2[[#This Row],[stock final au 10 juillet 2026]] -> 0 | K27: 46224 | L27: =VLOOKUP(Tableau2[[#This Row],[Code Article]],'ENTREE APRES INV'!A26:F1035,6,0) -> #N/A | M27: =VLOOKUP(Tableau2[[#This Row],[Code Article]],'SORTIE APRES INV'!A26:D436,4,0) -> #N/A
A28: IBATACCCR3030XXX | B28: Carreaux 30x30 | C28: 1 | D28: PIE | E28: 0 | F28: 0 | G28: =Tableau2[[#This Row],[STOCK FIN DECEMBRE 2024 SAGE]]+Tableau2[[#This Row],[Entrée 01 Janv 2025 au 10 juillet 2026]]-Tableau2[[#This Row],[sortie 01 Janv 2025 au 10 juillet 2026]] -> 1 | H28: 1 | I28: =Tableau2[[#This Row],[inventaire juillet 2026 ]]-Tableau2[[#This Row],[stock final au 10 juillet 2026]] -> 0 | K28: 46218 | L28: =VLOOKUP(Tableau2[[#This Row],[Code Article]],'ENTREE APRES INV'!A27:F1036,6,0) -> #N/A | M28: =VLOOKUP(Tableau2[[#This Row],[Code Article]],'SORTIE APRES INV'!A27:D437,4,0) -> #N/A
A29: NMXTCBLDC2X10YYY | B29: CABLE POWER,SHIELDED 10 M DC(S | C29: 10122 | D29: PIE | E29: 30035 | F29: =VLOOKUP(Tableau2[[#This Row],[Code Article]],SORTIE!A19:C406,3,FALSE) -> 40157 | G29: =Tableau2[[#This Row],[STOCK FIN DECEMBRE 2024 SAGE]]+Tableau2[[#This Row],[Entrée 01 Janv 2025 au 10 juillet 2026]]-Tableau2[[#This Row],[sortie 01 Janv 2025 au 10 juillet 2026]] -> 0 | I29: =Tableau2[[#This Row],[inventaire juillet 2026 ]]-Tableau2[[#This Row],[stock final au 10 juillet 2026]] -> 0 | K29: 46224 | L29: =VLOOKUP(Tableau2[[#This Row],[Code Article]],'ENTREE APRES INV'!A28:F1037,6,0) -> #N/A | M29: =VLOOKUP(Tableau2[[#This Row],[Code Article]],'SORTIE APRES INV'!A28:D438,4,0) -> #N/A
A30: TFHMANT30315HERC | B30: ANTENNE 3 A 0.3 15 HPX | C30: 4 | D30: PIE | E30: =VLOOKUP(Tableau2[[#This Row],[Code Article]],ENTREE!A13:C609,3,FALSE) -> 46 | F30: =VLOOKUP(Tableau2[[#This Row],[Code Article]],SORTIE!A20:C407,3,FALSE) -> 50 | G30: =Tableau2[[#This Row],[STOCK FIN DECEMBRE 2024 SAGE]]+Tableau2[[#This Row],[Entrée 01 Janv 2025 au 10 juillet 2026]]-Tableau2[[#This Row],[sortie 01 Janv 2025 au 10 juillet 2026]] -> 0 | I30: =Tableau2[[#This Row],[inventaire juillet 2026 ]]-Tableau2[[#This Row],[stock final au 10 juillet 2026]] -> 0 | K30: 46224 | L30: =VLOOKUP(Tableau2[[#This Row],[Code Article]],'ENTREE APRES INV'!A29:F1038,6,0) -> #N/A | M30: =VLOOKUP(Tableau2[[#This Row],[Code Article]],'SORTIE APRES INV'!A29:D439,4,0) -> #N/A
A31: TFHXIDUMDP400NEK | B31: MDP-400MB-1B (iPASOKINK200, 16 | C31: 2 | D31: PIE | E31: =VLOOKUP(Tableau2[[#This Row],[Code Article]],ENTREE!A14:C610,3,FALSE) -> 4 | F31: =VLOOKUP(Tableau2[[#This Row],[Code Article]],SORTIE!A21:C408,3,FALSE) -> 5 | G31: =Tableau2[[#This Row],[STOCK FIN DECEMBRE 2024 SAGE]]+Tableau2[[#This Row],[Entrée 01 Janv 2025 au 10 juillet 2026]]-Tableau2[[#This Row],[sortie 01 Janv 2025 au 10 juillet 2026]] -> 1 | H31: 1 | I31: =Tableau2[[#This Row],[inventaire juillet 2026 ]]-Tableau2[[#This Row],[stock final au 10 juillet 2026]] -> 0 | K31: 46217 | L31: =VLOOKUP(Tableau2[[#This Row],[Code Article]],'ENTREE APRES INV'!A30:F1039,6,0) -> #N/A | M31: =VLOOKUP(Tableau2[[#This Row],[Code Article]],'SORTIE APRES INV'!A30:D440,4,0) -> #N/A
A32: TFOXCFD12SA10NET | B32: Kit drop cable 1FO preco 2 sid | C32: 167 | D32: PIE | E32: 0 | F32: 0 | G32: =Tableau2[[#This Row],[STOCK FIN DECEMBRE 2024 SAGE]]+Tableau2[[#This Row],[Entrée 01 Janv 2025 au 10 juillet 2026]]-Tableau2[[#This Row],[sortie 01 Janv 2025 au 10 juillet 2026]] -> 167 | H32: 167 | I32: =Tableau2[[#This Row],[inventaire juillet 2026 ]]-Tableau2[[#This Row],[stock final au 10 juillet 2026]] -> 0 | K32: 46217 | L32: =VLOOKUP(Tableau2[[#This Row],[Code Article]],'ENTREE APRES INV'!A31:F1040,6,0) -> #N/A | M32: =VLOOKUP(Tableau2[[#This Row],[Code Article]],'SORTIE APRES INV'!A31:D441,4,0) -> #N/A
A33: TFOXCROILOVTSFLN | B33: Croix de Lovage Taille S FOLAN | C33: 1 | D33: PIE | E33: 0 | F33: 0 | G33: =Tableau2[[#This Row],[STOCK FIN DECEMBRE 2024 SAGE]]+Tableau2[[#This Row],[Entrée 01 Janv 2025 au 10 juillet 2026]]-Tableau2[[#This Row],[sortie 01 Janv 2025 au 10 juillet 2026]] -> 1 | H33: 1 | I33: =Tableau2[[#This Row],[inventaire juillet 2026 ]]-Tableau2[[#This Row],[stock final au 10 juillet 2026]] -> 0 | K33: 46216 | L33: =VLOOKUP(Tableau2[[#This Row],[Code Article]],'ENTREE APRES INV'!A32:F1041,6,0) -> #N/A | M33: =VLOOKUP(Tableau2[[#This Row],[Code Article]],'SORTIE APRES INV'!A32:D442,4,0) -> #N/A
A34: CINFSOUFIL116DEL | B34: Souris filaire Dell MS116 | C34: 2 | D34: PIE | E34: 0 | F34: 0 | G34: =Tableau2[[#This Row],[STOCK FIN DECEMBRE 2024 SAGE]]+Tableau2[[#This Row],[Entrée 01 Janv 2025 au 10 juillet 2026]]-Tableau2[[#This Row],[sortie 01 Janv 2025 au 10 juillet 2026]] -> 2 | H34: 2 | I34: =Tableau2[[#This Row],[inventaire juillet 2026 ]]-Tableau2[[#This Row],[stock final au 10 juillet 2026]] -> 0 | K34: 46224 | L34: =VLOOKUP(Tableau2[[#This Row],[Code Article]],'ENTREE APRES INV'!A33:F1042,6,0) -> #N/A | M34: =VLOOKUP(Tableau2[[#This Row],[Code Article]],'SORTIE APRES INV'!A33:D443,4,0) -> #N/A
A35: IGCVSEMANT1M2XXX | B35: Semelle trepied 1,20m | C35: 3 | D35: PIE | E35: 0 | F35: 0 | G35: =Tableau2[[#This Row],[STOCK FIN DECEMBRE 2024 SAGE]]+Tableau2[[#This Row],[Entrée 01 Janv 2025 au 10 juillet 2026]]-Tableau2[[#This Row],[sortie 01 Janv 2025 au 10 juillet 2026]] -> 3 | H35: 3 | I35: =Tableau2[[#This Row],[inventaire juillet 2026 ]]-Tableau2[[#This Row],[stock final au 10 juillet 2026]] -> 0 | K35: 46224 | L35: =VLOOKUP(Tableau2[[#This Row],[Code Article]],'ENTREE APRES INV'!A34:F1043,6,0) -> #N/A | M35: =VLOOKUP(Tableau2[[#This Row],[Code Article]],'SORTIE APRES INV'!A34:D444,4,0) -> #N/A
A36: NMXTBAT12V12APWR | B36: BATTERIE 12V 12Ah POWERSAFE | C36: 0 | D36: PIE | E36: =VLOOKUP(Tableau2[[#This Row],[Code Article]],ENTREE!A14:C615,3,FALSE) -> 4 | F36: =VLOOKUP(Tableau2[[#This Row],[Code Article]],SORTIE!A22:C413,3,FALSE) -> 4 | G36: =Tableau2[[#This Row],[STOCK FIN DECEMBRE 2024 SAGE]]+Tableau2[[#This Row],[Entrée 01 Janv 2025 au 10 juillet 2026]]-Tableau2[[#This Row],[sortie 01 Janv 2025 au 10 juillet 2026]] -> 0 | I36: =Tableau2[[#This Row],[inventaire juillet 2026 ]]-Tableau2[[#This Row],[stock final au 10 juillet 2026]] -> 0 | K36: 46224 | L36: =VLOOKUP(Tableau2[[#This Row],[Code Article]],'ENTREE APRES INV'!A35:F1044,6,0) -> #N/A | M36: =VLOOKUP(Tableau2[[#This Row],[Code Article]],'SORTIE APRES INV'!A35:D445,4,0) -> #N/A
A37: NMXTONDOL1100XXX | B37: ONDULEUR UPSON I 1100ONLINE MO | C37: 2 | D37: PIE | E37: 0 | F37: 0 | G37: =Tableau2[[#This Row],[STOCK FIN DECEMBRE 2024 SAGE]]+Tableau2[[#This Row],[Entrée 01 Janv 2025 au 10 juillet 2026]]-Tableau2[[#This Row],[sortie 01 Janv 2025 au 10 juillet 2026]] -> 2 | I37: =Tableau2[[#This Row],[inventaire juillet 2026 ]]-Tableau2[[#This Row],[stock final au 10 juillet 2026]] -> -2 | K37: 46224 | L37: =VLOOKUP(Tableau2[[#This Row],[Code Article]],'ENTREE APRES INV'!A36:F1045,6,0) -> #N/A | M37: =VLOOKUP(Tableau2[[#This Row],[Code Article]],'SORTIE APRES INV'!A36:D446,4,0) -> #N/A
A38: TCUIPEKR4XXXXGKA | B38: Peca R4 | C38: 6 | D38: PIE | E38: 0 | F38: 0 | G38: =Tableau2[[#This Row],[STOCK FIN DECEMBRE 2024 SAGE]]+Tableau2[[#This Row],[Entrée 01 Janv 2025 au 10 juillet 2026]]-Tableau2[[#This Row],[sortie 01 Janv 2025 au 10 juillet 2026]] -> 6 | H38: 6 | I38: =Tableau2[[#This Row],[inventaire juillet 2026 ]]-Tableau2[[#This Row],[stock final au 10 juillet 2026]] -> 0 | K38: 46224 | L38: =VLOOKUP(Tableau2[[#This Row],[Code Article]],'ENTREE APRES INV'!A37:F1046,6,0) -> #N/A | M38: =VLOOKUP(Tableau2[[#This Row],[Code Article]],'SORTIE APRES INV'!A37:D447,4,0) -> #N/A
A39: TFOXCBLS1FMUAGEK | B39: CABLE 1FO MULTI-USAGE G657A2 ( | C39: 4893 | D39: PIE | E39: =VLOOKUP(Tableau2[[#This Row],[Code Article]],ENTREE!A16:C618,3,FALSE) -> 4162 | F39: =VLOOKUP(Tableau2[[#This Row],[Code Article]],SORTIE!A23:C416,3,FALSE) -> 9055 | G39: =Tableau2[[#This Row],[STOCK FIN DECEMBRE 2024 SAGE]]+Tableau2[[#This Row],[Entrée 01 Janv 2025 au 10 juillet 2026]]-Tableau2[[#This Row],[sortie 01 Janv 2025 au 10 juillet 2026]] -> 0 | I39: =Tableau2[[#This Row],[inventaire juillet 2026 ]]-Tableau2[[#This Row],[stock final au 10 juillet 2026]] -> 0 | K39: 46224 | L39: =VLOOKUP(Tableau2[[#This Row],[Code Article]],'ENTREE APRES INV'!A38:F1047,6,0) -> 100 | M39: =VLOOKUP(Tableau2[[#This Row],[Code Article]],'SORTIE APRES INV'!A38:D448,4,0) -> #N/A
A40: TFOXTETOPTIQXXXX | B40: TETE OPTIQUE | C40: 9 | D40: PIE | E40: 0 | F40: =VLOOKUP(Tableau2[[#This Row],[Code Article]],SORTIE!A23:C417,3,FALSE) -> 6 | G40: =Tableau2[[#This Row],[STOCK FIN DECEMBRE 2024 SAGE]]+Tableau2[[#This Row],[Entrée 01 Janv 2025 au 10 juillet 2026]]-Tableau2[[#This Row],[sortie 01 Janv 2025 au 10 juillet 2026]] -> 3 | H40: 3 | I40: =Tableau2[[#This Row],[inventaire juillet 2026 ]]-Tableau2[[#This Row],[stock final au 10 juillet 2026]] -> 0 | K40: 46225 | L40: =VLOOKUP(Tableau2[[#This Row],[Code Article]],'ENTREE APRES INV'!A39:F1048,6,0) -> #N/A | M40: =VLOOKUP(Tableau2[[#This Row],[Code Article]],'SORTIE APRES INV'!A39:D449,4,0) -> #N/A
...

Sheet code sage
A1: CODE ARTICLE | B1: DESIGNATION_ARTICLE | C1: CODE_FAMILLE_ARTICLE | D1: DESIGNATION_FAMILLE | E1: CODE_SOUS_FAMILLE | F1: DESIGN_SOUS_FAMILLE_ART | G1: CLASSE | H1: UNITE | I1: STOCKE | J1: TAUX_TVA | K1: ARTICLE_GENERIQUE | L1: DATE_CREATION | M1: CODE SAGE TELMA | N1: CAT COMPTA TELMA
A2: 10000 | B2: FIXED CELLULAR TERMINAL GSMSLM | C2: TCO | D2: Telecom | E2: TCORADI | F2: Radio | G2: C | H2: PIE | I2: 0.00 | J2: 20.00 | K2: 0 | L2: 1 | M2: TMXTTRLFIXGSMXXX | N2: Equip Mixte-Tech
A3: 10001 | B3: Fixed Optical Attenuator(PCS) OFOAPCS00 | C3: RES | D3: Câbles et réseaux | E3: RESCBLT | F3: Câble Telecom et accessoires | G3: C | H3: PIE | I3: 0.00 | J3: 20.00 | K3: 0 | L3: 1 | M3: TFOXATTFIXOPTHAW | N3: FibreOptique-Fixe
A4: 10002 | B4: Fixed Optical Attenuator,1260nm~1620nm,7dB,LC/PC,45dB SSOPA | C4: TCO | D4: Telecom | E4: TCOTRNS | F4: Transmission | G4: C | H4: PIE | I4: 0.00 | J4: 20.00 | K4: 0 | L4: 1 | M4: TDWMATT1207DLHAW | N4: Réseau d'accès-Fixe
A5: 10003 | B5: Fixed Optical Attenuator,1260nm~1620nm10dBLC/PC45dB SSOPATN | C5: TCO | D5: Telecom | E5: TCOTRNS | F5: Transmission | G5: C | H5: PIE | I5: 0.00 | J5: 20.00 | K5: 0 | L5: 1 | M5: TDWMATT1210DLHAW | N5: Réseau d'accès-Fixe
A6: 10004 | B6: Fixed Optical Attenuator,1260nm~1620nm15dBLC/PC45dB SSOPATN | C6: TCO | D6: Telecom | E6: TCOTRNS | F6: Transmission | G6: C | H6: PIE | I6: 0.00 | J6: 20.00 | K6: 0 | L6: 1 | M6: TDWMATT1215DLHAW | N6: Réseau d'accès-Fixe
A7: 10005 | B7: Fixed Optical Attenuator,1260nm~1620nm5dBLC/PC45dB SSOPATNL | C7: TCO | D7: Telecom | E7: TCOTRNS | F7: Transmission | G7: C | H7: PIE | I7: 0.00 | J7: 20.00 | K7: 0 | L7: 1 | M7: TDWMATT1205DLHAW | N7: Réseau d'accès-Fixe
A8: 10006 | B8: FIXED SHELF FOR CABINET 10P | C8: RES | D8: Câbles et réseaux | E8: RESCBLT | F8: Câble Telecom et accessoires | G8: C | H8: PIE | I8: 0.00 | J8: 20.00 | K8: 0 | L8: 1 | M8: TFOXACCFIXC10XXX | N8: FibreOptique-Fixe
A9: 10007 | B9: FIXING FH ANTENNA SUPPORT | C9: PRM | D9: Prestations de maintenance | E9: PRMBATX | F9: Bâtiments | G9: C | H9: PIE | I9: 0.00 | J9: 20.00 | K9: 0 | L9: 1 | M9: IGCVFIXSUPAFHXXX | N9: GenieCivil-Fixe
A10: 10008 | B10: FLACON BIBON DE H2SO4 (ACIDE SULFURIQUE) | C10: TCO | D10: Telecom | E10: TCORADI | F10: Radio | G10: C | H10: PIE | I10: 0.00 | J10: 20.00 | K10: 0 | L10: 1 | M10: NMXTACDFH2SO4XXX | N10: Equip Mixte-Tech
A11: 10009 | B11: Flacon de DEXID 400 (5cc) | C11: MAT | D11: Matériaux de contruction | E11: MATQUIN | F11: QUINCAILLERIE | G11: C | H11: PIE | I11: 0.00 | J11: 20.00 | K11: 0 | L11: 1 | M11: PENTRDERDEX4005C | N11: Quincaillerie
A12: 10010 | B12: FLACON DISTRIBUTEUR D'ALCOOL | C12: TCO | D12: Telecom | E12: TCORADI | F12: Radio | G12: C | H12: PIE | I12: 0.00 | J12: 20.00 | K12: 0 | L12: 1 | M12: TMXTFLADISALCXXX | N12: Equip Mixte-Tech
A13: 10011 | B13: FLAT CABLE | C13: FRN | D13: Fournitures | E13: FRNPAPF | F13: fournitures&accessoires | G13: C | H13: PIE | I13: 0.00 | J13: 20.00 | K13: 0 | L13: 1 | M13: CINFCBLFLATCBXXX | N13: Frnt de bureau
... A1403: 11399 | B1403: PLC splitter 19, 10x 1:2 SC/APC | C1403: RES | D1403: Câbles et réseaux | E1403: RESCBLT | F1403: Câble Telecom et accessoires | G1403: C | H1403: PIE | I1403: 0.00 | J1403: 20.00 | K1403: 0 | L1403: 1 | M1403: TFOXSPL1912SCSPT | N1403: FibreOptique-Fixe
A1404: 114 | B1404: SUPPORT DE FIXATION BATTERIE | C1404: SOL | D1404: Equipement Solaire | E1404: SOLBATT | F1404: Batterie Solaire | G1404: C | H1404: UN | I1404: 0.00 | J1404: 20.00 | K1404: 0 | L1404: 1 | M1404: NMXTSUPBATXXXXXX
A1405: 11400 | B1405: PLC splitter 19, 6x 1:4 SC/APC | C1405: RES | D1405: Câbles et réseaux | E1405: RESCBLT | F1405: Câble Telecom et accessoires | G1405: C | H1405: PIE | I1405: 0.00 | J1405: 20.00 | K1405: 0 | L1405: 1 | M1405: TFOXSPL1914SCSPT | N1405: FibreOptique-Fixe
A1406: 11401 | B1406: PLC Splitter 1X16 Steel tube with bare fiber SM 1m pigtail | C1406: RES | D1406: Câbles et réseaux | E1406: RESCBLT | F1406: Câble Telecom et accessoires | G1406: C | H1406: PIE | I1406: 0.00 | J1406: 20.00 | K1406: 0 | L1406: 1 | M1406: TFOXSPL116S1MSPT | N1406: FibreOptique-Fixe
A1407: 11402 | B1407: PLC SPLITTER 1X8 STEEL TUBE WITH BARE FIBER SM 1m PIGTAIL A | C1407: RES | D1407: Câbles et réseaux | E1407: RESCBLT | F1407: Câble Telecom et accessoires | G1407: C | H1407: PIE | I1407: 0.00 | J1407: 20.00 | K1407: 0 | L1407: 1 | M1407: TFOXSPL1X8S1MSPT | N1407: FibreOptique-Fixe
A1408: 11403 | B1408: PLC splitter bare fiber, 1:8, 1,5m | C1408: RES | D1408: Câbles et réseaux | E1408: RESCBLT | F1408: Câble Telecom et accessoires | G1408: C | H1408: PIE | I1408: 0.00 | J1408: 20.00 | K1408: 0 | L1408: 1 | M1408: TFOXSPLBF1815SPT | N1408: FibreOptique-Fixe
A1409: 11404 | B1409: Plexi 5mm avec ferneture | C1409: MOE | D1409: Mobilier et équipements | E1409: MOEMOBB | F1409: Mobilier et équipements de bur | G1409: C | H1409: PIE | I1409: 0.00 | J1409: 20.00 | K1409: 0 | L1409: 1 | M1409: AMOIURNPLX5MMXXX | N1409: Mobilier de bureau
A1410: 11405 | B1410: Plinthe 50X85 mm | C1410: TCO | D1410: Telecom | E1410: TCOTRNS | F1410: Transmission | G1410: C | H1410: PIE | I1410: 0.00 | J1410: 20.00 | K1410: 0 | L1410: 1 | M1410: QLCEACCPLINTHXXX | N1410: Accessoires
A1411: 11406 | B1411: PLOT DE LESTAGE CABLE FO EN BETON | C1411: PRM | D1411: Prestations de maintenance | E1411: PRMBATX | F1411: Bâtiments | G1411: C | H1411: PIE | I1411: 0.00 | J1411: 20.00 | K1411: 0 | L1411: 1 | M1411: IGCVPLOCBLBETXXX | N1411: GenieCivil-Fixe
A1412: 11407 | B1412: pluggable client I/F for 1310nm, short reach, industrial tem | C1412: RES | D1412: Câbles et réseaux | E1412: RESCBIA | F1412: Fourn Informatique et accessoi | G1412: C | H1412: PIE | I1412: 0.00 | J1412: 20.00 | K1412: 0 | L1412: 1 | M1412: TSYNCON1310SMOSQ | N1412: Mat Infos
A1413: 11408 | B1413: PLUGIN UNIT/MMU2 B | C1413: TCO | D1413: Telecom | E1413: TCORADI | F1413: Radio | G1413: C | H1413: PIE | I1413: 0.00 | J1413: 20.00 | K1413: 0 | L1413: 1 | M1413: TMXTCRTMMU2BKXXX | N1413: Equip Mixte-Tech
A1414: 11409 | B1414: PLUGIN UNIT/PFM HOD BFB14013/1 | C1414: TCO | D1414: Telecom | E1414: TCOTRNS | F1414: Transmission | G1414: C | H1414: PIE | I1414: 0.00 | J1414: 20.00 | K1414: 0 | L1414: 1 | M1414: TGSNPLGPFMHODERC | N1414: Réseau d'accès-Av
A1415: 11410 | B1415: Plumier de bureau | C1415: FRN | D1415: Fournitures | E1415: FRNPAPF | F1415: fournitures&accessoires | G1415: C | H1415: PIE | I1415: 0.00 | J1415: 20.00 | K1415: 0 | L1415: 1 | M1415: FRNBPLUBURXXX631 | N1415: Frnt de bureau
A1416: 11411 | B1416: PM2200W DC Power Supply | C1416: RES | D1416: Câbles et réseaux | E1416: RESCBLT | F1416: Câble Telecom et accessoires | G1416: C | H1416: PIE | I1416: 0.00 | J1416: 20.00 | K1416: 0 | L1416: 1 | M1416: TFOXPOEPM2200HAW | N1416: FibreOptique-Fixe
... A1525: 11519 | B1525: Powersafe 12V 190Ah | C1525: TCO | D1525: Telecom | E1525: TCORADI | F1525: Radio | G1525: C | H1525: PIE | I1525: 0.00 | J1525: 20.00 | K1525: 0 | L1525: 1 | M1525: NMXTBAT12V190XXX | N1525: Equip Mixte-Tech
A1526: 1152 | B1526: COMBINAISON | C1526: SEC | D1526: Sécurité | E1526: SECSEPI | F1526: EPI | G1526: C | H1526: UN | I1526: 0.00 | J1526: 20.00 | K1526: 0 | L1526: 1 | M1526: HABILCOMBINPLXXX
A1527: 11520 | B1527: POYNTING CELLPHONE BOOSTER ANTENNA | C1527: TCO | D1527: Telecom | E1527: TCORADI | F1527: Radio | G1527: C | H1527: PIE | I1527: 0.00 | J1527: 20.00 | K1527: 0 | L1527: 1 | M1527: TMXTANTBOSCELXXX | N1527: Equip Mixte-Tech
A1528: 11521 | B1528: PP003G LOT 4 DE CARRES GRIS | C1528: MOE | D1528: Mobilier et équipements | E1528: MOEMOBB | F1528: Mobilier et équipements de bur | G1528: C | H1528: PIE | I1528: 0.00 | J1528: 20.00 | K1528: 0 | L1528: 1 | M1528: AMOIACCPP4CGRXXX | N1528: Mobilier de bureau
A1529: 11522 | B1529: PREAMPLIFICATEUR OPTIQUE | C1529: TCO | D1529: Telecom | E1529: TCORADI | F1529: Radio | G1529: C | H1529: PIE | I1529: 0.00 | J1529: 20.00 | K1529: 0 | L1529: 1 | M1529: TFHXAMPPREOPTSGM | N1529: Equip FH-Fixe
A1530: 11523 | B1530: PREDECOUPE | C1530: FRN | D1530: Fournitures | E1530: FRNPAPF | F1530: fournitures&accessoires | G1530: C | H1530: PIE | I1530: 0.00 | J1530: 20.00 | K1530: 0 | L1530: 1 | M1530: FRNBPAPPRDCPEXXX | N1530: Frnt de bureau
A1531: 11524 | B1531: PREPAYE GSM FIXE 1000 UT | C1531: TEL | D1531: Telephonie | E1531: TELTLPH | F1531: Telephone fixe et mobile avec | G1531: C | H1531: PIE | I1531: 0.00 | J1531: 20.00 | K1531: 0 | L1531: 1 | M1531: GSMFIXE1000UT | N1531: Terminaux
A1532: 11525 | B1532: PREPAYE GSM FIXE 1200 UT | C1532: TEL | D1532: Telephonie | E1532: TELTLPH | F1532: Telephone fixe et mobile avec | G1532: C | H1532: PIE | I1532: 0.00 | J1532: 20.00 | K1532: 0 | L1532: 1 | M1532: GSMFIXE1200UT | N1532: Terminaux
A1533: 11526 | B1533: PREPAYE GSM FIXE 150 UT | C1533: TEL | D1533: Telephonie | E1533: TELTLPH | F1533: Telephone fixe et mobile avec | G1533: C | H1533: PIE | I1533: 0.00 | J1533: 20.00 | K1533: 0 | L1533: 1 | M1533: GSMFIXE150UT | N1533: Terminaux
A1534: 11527 | B1534: PREPAYE GSM FIXE 300 UT | C1534: TEL | D1534: Telephonie | E1534: TELTLPH | F1534: Telephone fixe et mobile avec | G1534: C | H1534: PIE | I1534: 0.00 | J1534: 20.00 | K1534: 0 | L1534: 1 | M1534: GSMFIXE300UT | N1534: Terminaux
A1535: 11528 | B1535: PREPAYE GSM FIXE 500 UT | C1535: TEL | D1535: Telephonie | E1535: TELTLPH | F1535: Telephone fixe et mobile avec | G1535: C | H1535: PIE | I1535: 0.00 | J1535: 20.00 | K1535: 0 | L1535: 1 | M1535: GSMFIXE500UT | N1535: Terminaux
A1536: 11529 | B1536: PRESSE ETOUPE | C1536: TCO | D1536: Telecom | E1536: TCORADI | F1536: Radio | G1536: C | H1536: PIE | I1536: 0.00 | J1536: 20.00 | K1536: 0 | L1536: 1 | M1536: NMXTACCPRESETXXX | N1536: Equip Mixte-Tech
A1537: 11530 | B1537: PRESTATION ANIMATEUR | C1537: PRI | D1537: Prestations intellectuelles | E1537: PRICTRL | F1537: Prestation&service externe | G1537: C | H1537: PIE | I1537: 0.00 | J1537: 20.00 | K1537: 0 | L1537: 1 | M1537: PRSTANIMATEURXXX | N1537: Scexterne
...

Sheet SORTIE
A1: CODES | B1: designation | C1: QUANTITE | D1: date sortie | E1: verif sage
A2: TGSMTRC2219B8ERC | B2: Radio 2219 B8 Radio Unit | C2: 739 | D2: 45792 | E2: =VLOOKUP(A2,Tableau2[[Code Article]:[inventaire juillet 2026 ]],8,FALSE) -> 90
A3: TWMXIDUMBSCCHALV | B3: ALVARION | C3: 20 | D3: 45799 | E3: =VLOOKUP(A3,Tableau2[[Code Article]:[inventaire juillet 2026 ]],8,FALSE) -> 8
A4: TGSMCBLRTZ500ERC | B4: IF CABLE 7,6mm / TZC50097(500m) | C4: 16573 | D4: 45664 | E4: =VLOOKUP(A4,Tableau2[[Code Article]:[inventaire juillet 2026 ]],8,FALSE) -> 0
A5: TGSMTRC2219B3ERC | B5: Radio 2219 B3 Radio Unit_KRC161619/1 | C5: 559 | D5: 45666 | E5: =VLOOKUP(A5,Tableau2[[Code Article]:[inventaire juillet 2026 ]],8,FALSE) -> 9
A6: TGSMCBL78F500ERK | B6: """ FEEDER CABLE 7/8"""" 500M (01 DRUM OF 500M) """ | C6: 883 | D6: 45671 | E6: =VLOOKUP(A6,Tableau2[[Code Article]:[inventaire juillet 2026 ]],8,FALSE) -> 0
A7: TGSMPRUDUS411ERC | B7: "DUS 41 01,Digital unit" | C7: 4 | D7: 45673 | E7: =VLOOKUP(A7,Tableau2[[Code Article]:[inventaire juillet 2026 ]],8,FALSE) -> 5
A8: TGSMPROUDUW31ERC | B8: "DUW, 31 01 Digital Unit" | C8: 134 | D8: 45674 | E8: =VLOOKUP(A8,Tableau2[[Code Article]:[inventaire juillet 2026 ]],8,FALSE) -> 4
A9: TGSMPROUDUG20ERK | B9: PROCESSOR UNIT DUG 20 01,Digit | C9: 240 | D9: 45678 | E9: =VLOOKUP(A9,Tableau2[[Code Article]:[inventaire juillet 2026 ]],8,FALSE) -> 29
A10: TGSMCBLJU413MERC | B10: Rosenberger 1/2" jumper cable, | C10: 3063 | D10: 45680 | E10: =VLOOKUP(A10,Tableau2[[Code Article]:[inventaire juillet 2026 ]],8,FALSE) -> 0
A11: TGSMTRCRUS1B3ERC | B11: "TRANSCEIVER/RRUS 01 B3,Radio | C11: 11 | D11: 45790 | E11: =VLOOKUP(A11,Tableau2[[Code Article]:[inventaire juillet 2026 ]],8,FALSE) -> 1
A12: TGSMTRCRUS1B8ERC | B12: "TRANSCEIVER/RRUS 01B8,Radio U | C12: 95 | D12: 45685 | E12: =VLOOKUP(A12,Tableau2[[Code Article]:[inventaire juillet 2026 ]],8,FALSE) -> 0
A13: TGSMANTTC3HXXERC | B13: ANTENNA TRIPLE COLUMN 3H_61774 | C13: 36 | D13: 45720 | E13: =VLOOKUP(A13,Tableau2[[Code Article]:[inventaire juillet 2026 ]],8,FALSE) -> 0
... A45: TGSMANTM0678HERC | B45: ANTENNA/ANTm 0.6 7/8 HP/HPX | C45: 242 | D45: 45755 | E45: =VLOOKUP(A45,Tableau2[[Code Article]:[inventaire juillet 2026 ]],8,FALSE) -> 0
A46: TGSMANTDBC2HXERC | B46: ANTENNA DUAL COLUMN BAND 2H_61 | C46: 58 | D46: 30/01/25 ET 08/05/26 | E46: =VLOOKUP(A46,Tableau2[[Code Article]:[inventaire juillet 2026 ]],8,FALSE) -> 9
A47: TGSMANTXPL84XERK | B47: ANTENNA XPOL C-PANEL 806-960/8 | C47: 2 | D47: 45687 | E47: =VLOOKUP(A47,Tableau2[[Code Article]:[inventaire juillet 2026 ]],8,FALSE) -> 0
A48: TFHMANT30315HERC | B48: ANTENNA/ANTm 0.3 15 HP/HPX | C48: 50 | D48: 45792 | E48: =VLOOKUP(A48,Tableau2[[Code Article]:[inventaire juillet 2026 ]],8,FALSE) -> 0
A49: TGSMANTM0915HERC | B49: ANTENNA/ANTm 0.9 15 HP/HPX | C49: 44 | D49: 45799 | E49: =VLOOKUP(A49,Tableau2[[Code Article]:[inventaire juillet 2026 ]],8,FALSE) -> 0
A50: TGSMANT2478HPERK | B50: ANTENNE 2.4 | C50: 61 | D50: 45664 | E50: =VLOOKUP(A50,Tableau2[[Code Article]:[inventaire juillet 2026 ]],8,FALSE) -> 0
A51: MDIV000000354XXX | B51: ANTENNE 2STUCK LAT 56 DUO SET | C51: 1 | D51: 45666 | E51: =VLOOKUP(A51,Tableau2[[Code Article]:[inventaire juillet 2026 ]],8,FALSE) -> 0
A52: ANTINDOORHUAWEI | B52: ANTENNE CDMA | C52: 3 | D52: 45671 | E52: =VLOOKUP(A52,Tableau2[[Code Article]:[inventaire juillet 2026 ]],8,FALSE) -> 0
A53: TGSMANT127G11ERC | B53: ANTENNE FH 1.2 ERICSSON | C53: 180 | D53: 45673 | E53: =VLOOKUP(A53,Tableau2[[Code Article]:[inventaire juillet 2026 ]],8,FALSE) -> 0
A54: TGSMANT3BX790ERK | B54: ANTENNE Triple band antenna,XX | C54: 48 | D54: 45674 | E54: =VLOOKUP(A54,Tableau2[[Code Article]:[inventaire juillet 2026 ]],8,FALSE) -> 0
A55: ISPTISPANT519120UBI | B55: ANTENNE UBIQUITI | C55: 3 | D55: 45678 | E55: =VLOOKUP(A55,Tableau2[[Code Article]:[inventaire juillet 2026 ]],8,FALSE) -> 6
A56: TGSMANTDB8790ERC | B56: ANTENNE X/X-pol,790-960/1710-2170MHz,65/65deg,17.5/19.5dBiMET0-8 | C56: 12 | D56: 45680 | E56: =VLOOKUP(A56,Tableau2[[Code Article]:[inventaire juillet 2026 ]],8,FALSE) -> 0
A57: TGSMANTSB1790ERK | B57: ANTENNE X-pol.790-960MHz,65deg | C57: 63 | D57: 45790 | E57: =VLOOKUP(A57,Tableau2[[Code Article]:[inventaire juillet 2026 ]],8,FALSE) -> 0
A58: TGSMANTSECDBDERK | B58: ANTENNES SECTORIELLES DOUBLE | C58: 42 | D58: 45685 | E58: =VLOOKUP(A58,Tableau2[[Code Article]:[inventaire juillet 2026 ]],8,FALSE) -> 0
... A88: TGSMBAT6313XXERC | B88: Battery 6313_BKB90290/2 | C88: 1 | D88: 45694 | E88: =VLOOKUP(A88,Tableau2[[Code Article]:[inventaire juillet 2026 ]],8,FALSE) -> 0
A89: NMXTBATC90C5BXXX | B89: BATTERY CABLE HALOGEN FREE, 90C, 50MM2 BLACK,TFL103106 00 | C89: 330 | D89: 11/07/25 et 05/12/25 | E89: =VLOOKUP(A89,Tableau2[[Code Article]:[inventaire juillet 2026 ]],8,FALSE) -> 28
A90: NMXTCBL90C35MERC | B90: Battery Cable, Halogenfree, 90 C, 35 MM2, GREY, 30 m | C90: 5 | D90: 05/03/25 et 07/11/25 | E90: =VLOOKUP(A90,Tableau2[[Code Article]:[inventaire juillet 2026 ]],8,FALSE) -> 0
A91: TGSMBFU0103BFERC | B91: BATTERY FUSE UNIT BFU 01 03 Battery Fuse | C91: 22 | D91: 05/03/25 et 07/11/25 | E91: =VLOOKUP(A91,Tableau2[[Code Article]:[inventaire juillet 2026 ]],8,FALSE) -> 0
A92: NMXTBAT48V60AERC | B92: Battery Set 48V / 60Ah NSB Silver FT | C92: 28 | D92: 05/03/25 et 07/11/25 | E92: =VLOOKUP(A92,Tableau2[[Code Article]:[inventaire juillet 2026 ]],8,FALSE) -> 0
A93: NMXTBAT100BLUERC | B93: BATTERY/NSB 100 BLUE+ (4x12V) 100Ah_BKC90106/160 | C93: 21 | D93: 05/03/25 et 07/11/25 | E93: =VLOOKUP(A93,Tableau2[[Code Article]:[inventaire juillet 2026 ]],8,FALSE) -> 0
A94: TGSMBBSOU6102ERC | B94: BBS 6102 | C94: 1 | D94: 05/03/25 et 07/11/25 | E94: =VLOOKUP(A94,Tableau2[[Code Article]:[inventaire juillet 2026 ]],8,FALSE) -> 0
A95: TGSMBFU0101BFERC | B95: BFU 0101 | C95: 4 | D95: 05/03/25 et 07/11/25 | E95: =VLOOKUP(A95,Tableau2[[Code Article]:[inventaire juillet 2026 ]],8,FALSE) -> 4
A96: TGSMBFU0102BFERC | B96: BFU0102 | C96: 15 | D96: 05/03/25 et 07/11/25 | E96: =VLOOKUP(A96,Tableau2[[Code Article]:[inventaire juillet 2026 ]],8,FALSE) -> 0
A97: NMXTBIDVIDXXXXXX | B97: BIDON VIDE | C97: 69 | D97: 05/03/25 et 07/11/25 | E97: =VLOOKUP(A97,Tableau2[[Code Article]:[inventaire juillet 2026 ]],8,FALSE) -> 0
A98: TMXTRTROHG85HHAW | B98: HUAWEI(divers) | C98: 171 | D98: 05/03/25 et 07/11/25 | E98: =VLOOKUP(A98,Tableau2[[Code Article]:[inventaire juillet 2026 ]],8,FALSE) -> 15
A99: MPLV000004128XXX | B99: BUNTING TELMA/MVOLA | C99: 1 | D99: 05/03/25 et 07/11/25 | E99: =VLOOKUP(A99,Tableau2[[Code Article]:[inventaire juillet 2026 ]],8,FALSE) -> 0
A100: TFOXCBLOP12STXXX | B100: cable 12FO coupon | C100: 2588 | D100: 05/03/25 et 07/11/25 | E100: =VLOOKUP(A100,Tableau2[[Code Article]:[inventaire juillet 2026 ]],8,FALSE) -> 0
...

Sheet ENTREE APRES INV
A1: CODE ARTICLE | B1: PROVENANCE | C1: DESIGNATION | D1: REF FMR | E1: DATE DE RECEPTION | F1: QUANTITE RECU | G1: UNITE | H1: LOCAL | I1: STATU | J1: OBSERVATION | K1: PRESTATAIRE
A2: ISPTMXTRTR951UI2XXX | B2: ANALAKELY 3M ETAGE | C2: ROUTERBOARD RB951UI-2HND | D2: 4023/26/DTG/LOG | E2: 46226 | F2: 1 | G2: PIE | H2: Ilafy | I2: RECU | J2: A METTRE AU REBUT | K2: DTG
A3: ISPTMXTRTR951UI2XXX | B3: ANALAKELY 3M ETAGE | C3: ROUTERBOARD RB951UI-2HND | D3: 4023/26/DTG/LOG | E3: 46226 | F3: 1 | G3: PIE | H3: Ilafy | I3: RECU | J3: A METTRE AU REBUT | K3: DTG
A4: ISPTMXTRTR951UI2XXX | B4: ANALAKELY 3M ETAGE | C4: ROUTERBOARD RB951UI-2HND | D4: 4023/26/DTG/LOG | E4: 46226 | F4: 1 | G4: PIE | H4: Ilafy | I4: RECU | J4: A METTRE AU REBUT | K4: DTG
A5: ISPTMXTRTR951UI2XXX | B5: ANALAKELY 3M ETAGE | C5: ROUTERBOARD RB951UI-2HND | D5: 4023/26/DTG/LOG | E5: 46226 | F5: 1 | G5: PIE | H5: Ilafy | I5: RECU | J5: A METTRE AU REBUT | K5: DTG
A6: ISPTMXTRTR951UI2XXX | B6: ANALAKELY 3M ETAGE | C6: ROUTERBOARD RB951UI-2HND | D6: 4023/26/DTG/LOG | E6: 46226 | F6: 1 | G6: PIE | H6: Ilafy | I6: RECU | J6: A METTRE AU REBUT | K6: DTG
A7: ISPTMXTRTR951UI2XXX | B7: ANALAKELY 3M ETAGE | C7: ROUTERBOARD RB951UI-2HND | D7: 4023/26/DTG/LOG | E7: 46226 | F7: 1 | G7: PIE | H7: Ilafy | I7: RECU | J7: A METTRE AU REBUT | K7: DTG
A8: ISPTMXTRTR951UI2XXX | B8: ANALAKELY 3M ETAGE | C8: ROUTERBOARD RB951UI-2HND | D8: 4023/26/DTG/LOG | E8: 46226 | F8: 1 | G8: PIE | H8: Ilafy | I8: RECU | J8: A METTRE AU REBUT | K8: DTG
A9: ISPTMXTRTR951UI2XXX | B9: ANALAKELY 3M ETAGE | C9: ROUTERBOARD RB951UI-2HND | D9: 4023/26/DTG/LOG | E9: 46226 | F9: 1 | G9: PIE | H9: Ilafy | I9: RECU | J9: A METTRE AU REBUT | K9: DTG
A10: ISPTMXTRTR951UI2XXX | B10: ANALAKELY 3M ETAGE | C10: ROUTERBOARD RB951UI-2HND | D10: 4023/26/DTG/LOG | E10: 46226 | F10: 1 | G10: PIE | H10: Ilafy | I10: RECU | J10: A METTRE AU REBUT | K10: DTG
A11: ISPTMXTRTR951UI2XXX | B11: ANALAKELY 3M ETAGE | C11: ROUTERBOARD RB951UI-2HND | D11: 4023/26/DTG/LOG | E11: 46226 | F11: 1 | G11: PIE | H11: Ilafy | I11: RECU | J11: A METTRE AU REBUT | K11: DTG
A12: ISPTMXTRTR951UI2XXX | B12: ANALAKELY 3M ETAGE | C12: ROUTERBOARD RB951UI-2HND | D12: 4023/26/DTG/LOG | E12: 46226 | F12: 1 | G12: PIE | H12: Ilafy | I12: RECU | J12: A METTRE AU REBUT | K12: DTG
A13: ISPTMXTRTR951UI2XXX | B13: ANALAKELY 3M ETAGE | C13: ROUTERBOARD RB951UI-2HND | D13: 4023/26/DTG/LOG | E13: 46226 | F13: 1 | G13: PIE | H13: Ilafy | I13: RECU | J13: A METTRE AU REBUT | K13: DTG
... A280: TMXTBATTPHMBLXXX | B280: ANDRAHARO | C280: MINI BATTERIE | D280: 130826/DHSE | E280: 46247 | F280: 1 | G280: PIE | H280: Ilafy | I280: RECU | J280: A METTRE AU REBUT | K280: HSSES
B281: ANDRAHARO | C281: MINI ONDEULEUR | D281: 130826/DHSE | E281: 46247 | F281: 1 | G281: PIE | H281: Ilafy | I281: RECU | J281: A METTRE AU REBUT | K281: HSSES
B282: ANDRAHARO | C282: MINI MONTRE | D282: 130826/DHSE | E282: 46247 | F282: 1 | G282: PIE | H282: Ilafy | I282: RECU | J282: A METTRE AU REBUT | K282: HSSES
B283: ANDRAHARO | C283: OTG | D283: 130826/DHSE | E283: 46247 | F283: 1 | G283: PIE | H283: Ilafy | I283: RECU | J283: A METTRE AU REBUT | K283: HSSES
B284: ANDRAHARO | C284: PORT TELEPHONE | D284: 130826/DHSE | E284: 46247 | F284: 1 | G284: PIE | H284: Ilafy | I284: RECU | J284: A METTRE AU REBUT | K284: HSSES
B285: ANDRAHARO | C285: ROTATING ANTENNA TV | D285: 130826/DHSE | E285: 46247 | F285: 1 | G285: PIE | H285: Ilafy | I285: RECU | J285: A METTRE AU REBUT | K285: HSSES
B286: ANDRAHARO | C286: SOURIS | D286: 130826/DHSE | E286: 46247 | F286: 1 | G286: PIE | H286: Ilafy | I286: RECU | J286: A METTRE AU REBUT | K286: HSSES
B287: ANDRAHARO | C287: SPEAKER | D287: 130826/DHSE | E287: 46247 | F287: 1 | G287: PIE | H287: Ilafy | I287: RECU | J287: A METTRE AU REBUT | K287: HSSES
B288: ANDRAHARO | C288: TABLETTE | D288: 130826/DHSE | E288: 46247 | F288: 1 | G288: PIE | H288: Ilafy | I288: RECU | J288: A METTRE AU REBUT | K288: HSSES
B289: ANDRAHARO | C289: TELECOMMANDE | D289: 130826/DHSE | E289: 46247 | F289: 1 | G289: PIE | H289: Ilafy | I289: RECU | J289: A METTRE AU REBUT | K289: HSSES
B290: ANDRAHARO | C290: TELEPHONES/SMARTPHONES | D290: 130826/DHSE | E290: 46247 | F290: 12 | G290: PIE | H290: Ilafy | I290: RECU | J290: A METTRE AU REBUT | K290: HSSES
B291: ANDRAHARO | C291: THERMOMETRE | D291: 130826/DHSE | E291: 46247 | F291: 1 | G291: PIE | H291: Ilafy | I291: RECU | J291: A METTRE AU REBUT | K291: HSSES
B292: ANDRAHARO | C292: USB | D292: 130826/DHSE | E292: 46247 | F292: 1 | G292: PIE | H292: Ilafy | I292: RECU | J292: A METTRE AU REBUT | K292: HSSES
... B295: ANALAKELY | C295: ARMOIRE METHALLIQUE | D295: 229/26-MAINT-LOG | E295: 46252 | F295: 3 | G295: PIE | H295: Ilafy | I295: RECU | J295: A METTRE AU REBUT | K295: MAINTENANCE
A296: TMXTREBD3EGENXXX | B296: ANALAKELY | C296: CARTE OCB | D296: 4135/26/DTG/LOG | E296: 46254 | F296: 904 | G296: PIE | H296: Ilafy | I296: RECU | J296: A METTRE AU REBUT | K296: ONIX
A297: TMXTREBD3EGENXXX | B297: ANALAKELY | C297: CARTE OCB GM | D297: 4135/26/DTG/LOG | E297: 46254 | F297: 70 | G297: PIE | H297: Ilafy | I297: RECU | J297: A METTRE AU REBUT | K297: ONIX
A298: TMXTREBD3EGENXXX | B298: ANALAKELY | C298: ACCESSOIRE RACK | D298: 4135/26/DTG/LOG | E298: 46254 | F298: 167 | G298: PIE | H298: Ilafy | I298: RECU | J298: A METTRE AU REBUT | K298: ONIX
A299: TMXTREBD3EGENXXX | B299: ANALAKELY | C299: PORTE RACK | D299: 4135/26/DTG/LOG | E299: 46254 | F299: 2 | G299: PIE | H299: Ilafy | I299: RECU | J299: A METTRE AU REBUT | K299: ONIX
A300: TMXTREBD3EGENXXX | B300: ANALAKELY | C300: COFFRET ALCATEL | D300: 4135/26/DTG/LOG | E300: 46254 | F300: 1 | G300: PIE | H300: Ilafy | I300: RECU | J300: A METTRE AU REBUT | K300: ONIX
A301: TMXTREBD3EGENXXX | B301: ANALAKELY | C301: CARTE PM | D301: 4138/26/DTG/LOG | E301: 46259 | F301: 456 | G301: PIE | H301: Ilafy | I301: RECU | J301: A METTRE AU REBUT | K301: ONIX
A302: TMXTREBD3EGENXXX | B302: ANALAKELY | C302: CARTE GM | D302: 4138/26/DTG/LOG | E302: 46259 | F302: 72 | G302: PIE | H302: Ilafy | I302: RECU | J302: A METTRE AU REBUT | K302: ONIX
A303: TMXTREBD3EGENXXX | B303: ANALAKELY | C303: INTERFACE | D303: 4138/26/DTG/LOG | E303: 46259 | F303: 860 | G303: PIE | H303: Ilafy | I303: RECU | J303: A METTRE AU REBUT | K303: ONIX
A304: TMXTREBD3EGENXXX | B304: ANALAKELY | C304: CONVERTER ALCATEL | D304: 4138/26/DTG/LOG | E304: 46259 | F304: 61 | G304: PIE | H304: Ilafy | I304: RECU | J304: A METTRE AU REBUT | K304: ONIX
A305: TMXTREBD3EGENXXX | B305: ANALAKELY | C305: CONVERTER | D305: 4138/26/DTG/LOG | E305: 46259 | F305: 27 | G305: PIE | H305: Ilafy | I305: RECU | J305: A METTRE AU REBUT | K305: ONIX
A306: TMXTREBD3EGENXXX | B306: ANALAKELY | C306: RACCORDEMENT | D306: 4138/26/DTG/LOG | E306: 46259 | F306: 5 | G306: PIE | H306: Ilafy | I306: RECU | J306: A METTRE AU REBUT | K306: ONIX
A307: TMXTREBD3EGENXXX | B307: ANALAKELY | C307: ACCESSOIRE | D307: 4138/26/DTG/LOG | E307: 46259 | F307: 149 | G307: PIE | H307: Ilafy | I307: RECU | J307: A METTRE AU REBUT | K307: ONIX
... A323: EELAECOUBLUTHXXX | B323: NOC | C323: ECOUTEUR A CASQUE | D323: 0002-26/DHSE | E323: 46259 | F323: 1 | G323: LOT | H323: Ilafy | I323: RECU | J323: A METTRE AU REBUT | K323: HSSES
...

Sheet SORTIE APRES INV
A1: Date d'enlèvement | B1: Code articles | C1: Article Description | D1: Quantité | E1: Unité | F1: Méthode de traitement / d'élimination | G1: NUMERO BSD | H1: FMR/GDA | I1: DATE D'ENLEVEMENT | J1: N° BL | K1: DESTINATION
A2: 46237 | C2: POTEAU EN BOIS | D2: 42 | E2: PIE | F2: M. OLIVIER ROZIERE | G2: BSD300726 | H2: 4089/25/DTG/LOG | I2: 46237 | J2: 146/26-REVLOG | K2: M. OLIVIER ROZIERE
A3: 46241 | B3: TMXTREBD3EGENXXX | C3: RACK OCB ALCATEL 2,10X0,66m | D3: 30 | E3: PIE | F3: VALOMADA | G3: BSD070826 | H3: 4082/26/DTG/LOG | I3: 46241 | J3: 147/26-REVLOG | K3: VALOMADA
A4: 46241 | B4: TMXTREBD3EGENXXX | C4: PORTE DE RACK 2,00x0,45m | D4: 104 | E4: PIE | F4: VALOMADA | G4: BSD070826 | H4: 4082/26/DTG/LOG | I4: 46241 | J4: 147/26-REVLOG | K4: VALOMADA
A5: 46241 | B5: TMXTREBD3EGENXXX | C5: PANNEAU LATERAL 2,20x 0,66m | D5: 10 | E5: PIE | F5: VALOMADA | G5: BSD070826 | H5: 4082/26/DTG/LOG | I5: 46241 | J5: 147/26-REVLOG | K5: VALOMADA
A6: 46241 | B6: TMXTREBD3EGENXXX | C6: CAPOT SUPERIEUR RACK 0,90X0,60 | D6: 30 | E6: PIE | F6: VALOMADA | G6: BSD070826 | H6: 4082/26/DTG/LOG | I6: 46241 | J6: 147/26-REVLOG | K6: VALOMADA
A7: 46241 | B7: TMXTREBD3EGENXXX | C7: SUPPORT CAPOT 0,15X0,95m | D7: 10 | E7: PIE | F7: VALOMADA | G7: BSD070826 | H7: 4082/26/DTG/LOG | I7: 46241 | J7: 147/26-REVLOG | K7: VALOMADA
A8: 46241 | B8: TMXTREBD3EGENXXX | C8: SUPPORT CAPOT 0,25X0,95m | D8: 9 | E8: PIE | F8: VALOMADA | G8: BSD070826 | H8: 4082/26/DTG/LOG | I8: 46241 | J8: 147/26-REVLOG | K8: VALOMADA
A9: 46246 | B9: TGSMANT21278HERC | C9: ANTENNA/ANTm1.2 | D9: 1 | E9: PIE | F9: VALOMADA | G9: BSD120826 | H9: 4045/26/DTG/LOG | I9: 46246 | J9: 148/26-REVLOG | K9: VALOMADA
A10: 46246 | B10: TFOXCFD12SA10NET | C10: CABLE 1FO | D10: 430 | E10: M | F10: VALOMADA | G10: BSD120827 | H10: 3799/26/DTG/LOG | I10: 46246 | J10: 148/26-REVLOG | K10: VALOMADA
A11: 46246 | B11: TMXTREBD3EGENXXX | C11: CABLE JARETIERE | D11: 1250 | E11: M | F11: VALOMADA | G11: BSD120828 | H11: 3799/26/DTG/LOG | I11: 46246 | J11: 148/26-REVLOG | K11: VALOMADA
